Watching for file changes with StatReloader
Waiting for apps ready_event.
Apps ready_event triggered. Sending autoreload_started signal.
Watching dir D:\L3\Y2\Unit 27\Wiki\mywiki27\locale with glob **/*.mo.
Watching dir D:\L3\Y2\Unit 27\Wiki\mywiki27\wiki\locale with glob **/*.mo.
Watching dir C:\Users\402995\AppData\Roaming\Python\Python36\site-packages\django\contrib\admin\locale with glob **/*.mo.
Watching dir C:\Users\402995\AppData\Roaming\Python\Python36\site-packages\django\contrib\auth\locale with glob **/*.mo.
Watching dir C:\Users\402995\AppData\Roaming\Python\Python36\site-packages\django\contrib\contenttypes\locale with glob **/*.mo.
Watching dir C:\Users\402995\AppData\Roaming\Python\Python36\site-packages\django\contrib\sessions\locale with glob **/*.mo.
Watching dir C:\Users\402995\AppData\Roaming\Python\Python36\site-packages\django\contrib\messages\locale with glob **/*.mo.
Watching dir C:\Users\402995\AppData\Roaming\Python\Python36\site-packages\django\contrib\staticfiles\locale with glob **/*.mo.
(0.000) 
            SELECT name, type FROM sqlite_master
            WHERE type in ('table', 'view') AND NOT name='sqlite_sequence'
            ORDER BY name; args=None
(0.000) SELECT "django_migrations"."app", "django_migrations"."name" FROM "django_migrations"; args=()


Internal Server Error: /wiki/
Traceback (most recent call last):
  File "C:\Users\402995\AppData\Roaming\Python\Python36\site-packages\django\template\base.py", line 470, in parse
    compile_func = self.tags[command]
KeyError: 'request.user.username'

During handling of the above exception, another exception occurred:

Traceback (most recent call last):
  File "C:\Users\402995\AppData\Roaming\Python\Python36\site-packages\django\core\handlers\exception.py", line 34, in inner
    response = get_response(request)
  File "C:\Users\402995\AppData\Roaming\Python\Python36\site-packages\django\core\handlers\base.py", line 145, in _get_response
    response = self.process_exception_by_middleware(e, request)
  File "C:\Users\402995\AppData\Roaming\Python\Python36\site-packages\django\core\handlers\base.py", line 143, in _get_response
    response = response.render()
  File "C:\Users\402995\AppData\Roaming\Python\Python36\site-packages\django\template\response.py", line 106, in render
    self.content = self.rendered_content
  File "C:\Users\402995\AppData\Roaming\Python\Python36\site-packages\django\template\response.py", line 81, in rendered_content
    template = self.resolve_template(self.template_name)
  File "C:\Users\402995\AppData\Roaming\Python\Python36\site-packages\django\template\response.py", line 63, in resolve_template
    return select_template(template, using=self.using)
  File "C:\Users\402995\AppData\Roaming\Python\Python36\site-packages\django\template\loader.py", line 42, in select_template
    return engine.get_template(template_name)
  File "C:\Users\402995\AppData\Roaming\Python\Python36\site-packages\django\template\backends\django.py", line 34, in get_template
    return Template(self.engine.get_template(template_name), self)
  File "C:\Users\402995\AppData\Roaming\Python\Python36\site-packages\django\template\engine.py", line 143, in get_template
    template, origin = self.find_template(template_name)
  File "C:\Users\402995\AppData\Roaming\Python\Python36\site-packages\django\template\engine.py", line 125, in find_template
    template = loader.get_template(name, skip=skip)
  File "C:\Users\402995\AppData\Roaming\Python\Python36\site-packages\django\template\loaders\base.py", line 30, in get_template
    contents, origin, origin.template_name, self.engine,
  File "C:\Users\402995\AppData\Roaming\Python\Python36\site-packages\django\template\base.py", line 156, in __init__
    self.nodelist = self.compile_nodelist()
  File "C:\Users\402995\AppData\Roaming\Python\Python36\site-packages\django\template\base.py", line 194, in compile_nodelist
    return parser.parse()
  File "C:\Users\402995\AppData\Roaming\Python\Python36\site-packages\django\template\base.py", line 478, in parse
    raise self.error(token, e)
  File "C:\Users\402995\AppData\Roaming\Python\Python36\site-packages\django\template\base.py", line 476, in parse
    compiled_result = compile_func(self, token)
  File "C:\Users\402995\AppData\Roaming\Python\Python36\site-packages\django\template\loader_tags.py", line 266, in do_extends
    nodelist = parser.parse()
  File "C:\Users\402995\AppData\Roaming\Python\Python36\site-packages\django\template\base.py", line 478, in parse
    raise self.error(token, e)
  File "C:\Users\402995\AppData\Roaming\Python\Python36\site-packages\django\template\base.py", line 476, in parse
    compiled_result = compile_func(self, token)
  File "C:\Users\402995\AppData\Roaming\Python\Python36\site-packages\django\template\loader_tags.py", line 209, in do_block
    nodelist = parser.parse(('endblock',))
  File "C:\Users\402995\AppData\Roaming\Python\Python36\site-packages\django\template\base.py", line 472, in parse
    self.invalid_block_tag(token, command, parse_until)
  File "C:\Users\402995\AppData\Roaming\Python\Python36\site-packages\django\template\base.py", line 528, in invalid_block_tag
    get_text_list(["'%s'" % p for p in parse_until], 'or'),
django.template.exceptions.TemplateSyntaxError: Invalid block tag on line 26: 'request.user.username', expected 'endblock'. Did you forget to register or load this tag?
"GET /wiki/ HTTP/1.1" 500 151928
Internal Server Error: /wiki/
Traceback (most recent call last):
  File "C:\Users\402995\AppData\Roaming\Python\Python36\site-packages\django\core\handlers\exception.py", line 34, in inner
    response = get_response(request)
  File "C:\Users\402995\AppData\Roaming\Python\Python36\site-packages\django\core\handlers\base.py", line 145, in _get_response
    response = self.process_exception_by_middleware(e, request)
  File "C:\Users\402995\AppData\Roaming\Python\Python36\site-packages\django\core\handlers\base.py", line 143, in _get_response
    response = response.render()
  File "C:\Users\402995\AppData\Roaming\Python\Python36\site-packages\django\template\response.py", line 106, in render
    self.content = self.rendered_content
  File "C:\Users\402995\AppData\Roaming\Python\Python36\site-packages\django\template\response.py", line 81, in rendered_content
    template = self.resolve_template(self.template_name)
  File "C:\Users\402995\AppData\Roaming\Python\Python36\site-packages\django\template\response.py", line 63, in resolve_template
    return select_template(template, using=self.using)
  File "C:\Users\402995\AppData\Roaming\Python\Python36\site-packages\django\template\loader.py", line 42, in select_template
    return engine.get_template(template_name)
  File "C:\Users\402995\AppData\Roaming\Python\Python36\site-packages\django\template\backends\django.py", line 34, in get_template
    return Template(self.engine.get_template(template_name), self)
  File "C:\Users\402995\AppData\Roaming\Python\Python36\site-packages\django\template\engine.py", line 143, in get_template
    template, origin = self.find_template(template_name)
  File "C:\Users\402995\AppData\Roaming\Python\Python36\site-packages\django\template\engine.py", line 125, in find_template
    template = loader.get_template(name, skip=skip)
  File "C:\Users\402995\AppData\Roaming\Python\Python36\site-packages\django\template\loaders\base.py", line 30, in get_template
    contents, origin, origin.template_name, self.engine,
  File "C:\Users\402995\AppData\Roaming\Python\Python36\site-packages\django\template\base.py", line 156, in __init__
    self.nodelist = self.compile_nodelist()
  File "C:\Users\402995\AppData\Roaming\Python\Python36\site-packages\django\template\base.py", line 194, in compile_nodelist
    return parser.parse()
  File "C:\Users\402995\AppData\Roaming\Python\Python36\site-packages\django\template\base.py", line 478, in parse
    raise self.error(token, e)
  File "C:\Users\402995\AppData\Roaming\Python\Python36\site-packages\django\template\base.py", line 476, in parse
    compiled_result = compile_func(self, token)
  File "C:\Users\402995\AppData\Roaming\Python\Python36\site-packages\django\template\loader_tags.py", line 266, in do_extends
    nodelist = parser.parse()
  File "C:\Users\402995\AppData\Roaming\Python\Python36\site-packages\django\template\base.py", line 478, in parse
    raise self.error(token, e)
  File "C:\Users\402995\AppData\Roaming\Python\Python36\site-packages\django\template\base.py", line 476, in parse
    compiled_result = compile_func(self, token)
  File "C:\Users\402995\AppData\Roaming\Python\Python36\site-packages\django\template\loader_tags.py", line 209, in do_block
    nodelist = parser.parse(('endblock',))
  File "C:\Users\402995\AppData\Roaming\Python\Python36\site-packages\django\template\base.py", line 478, in parse
    raise self.error(token, e)
  File "C:\Users\402995\AppData\Roaming\Python\Python36\site-packages\django\template\base.py", line 476, in parse
    compiled_result = compile_func(self, token)
  File "C:\Users\402995\AppData\Roaming\Python\Python36\site-packages\django\template\loader_tags.py", line 199, in do_block
    raise TemplateSyntaxError("'%s' tag takes only one argument" % bits[0])
django.template.exceptions.TemplateSyntaxError: 'block' tag takes only one argument
"GET /wiki/ HTTP/1.1" 500 152190
Not Found: /
"GET / HTTP/1.1" 404 2155
Not Found: /favicon.ico
"GET /favicon.ico HTTP/1.1" 404 2206
Not Found: /
"GET / HTTP/1.1" 404 2155
Not Found: /
"GET / HTTP/1.1" 404 2155
Not Found: /accounts/login/
Not Found: /wiki/Testpage/edit/
Not Found: /
"GET / HTTP/1.1" 404 2155
Not Found: /favicon.ico
"GET /favicon.ico HTTP/1.1" 404 2206
Not Found: /wiki/Testpage/edit/
Not Found: /wiki/Testpage/edit/
Not Found: /
"GET / HTTP/1.1" 404 2155
Not Found: /favicon.ico
"GET /favicon.ico HTTP/1.1" 404 2206
Not Found: /accounts/login/
"GET /accounts/login/?next=/wiki/The%2520Tuareg/edit HTTP/1.1" 404 2249
Not Found: /wiki/Testpage/edit/
Not Found: /wiki/Testpage/edit/
Not Found: /accounts/login/
"GET /accounts/login/?next=/wiki/The%2520Tuareg/save HTTP/1.1" 404 2249
Not Found: /wiki/Testpage/edit/
Not Found: /wiki/Testpage/edit/
Not Found: /wiki/Testpage/edit/
Not Found: /accounts/login/
"GET /accounts/login/?next=/wiki/The%2520Tuareg/edit HTTP/1.1" 404 2249
Not Found: /accounts/login/
"GET /accounts/login/?next=/wiki/The%2520Tuareg/edit HTTP/1.1" 404 2249
Not Found: /accounts/login/
"GET /accounts/login/?next=/wiki/The%2520Tuareg/edit HTTP/1.1" 404 2249
Internal Server Error: /accounts/login/
Traceback (most recent call last):
  File "C:\Users\402995\AppData\Roaming\Python\Python36\site-packages\django\core\handlers\exception.py", line 34, in inner
    response = get_response(request)
  File "C:\Users\402995\AppData\Roaming\Python\Python36\site-packages\django\core\handlers\base.py", line 145, in _get_response
    response = self.process_exception_by_middleware(e, request)
  File "C:\Users\402995\AppData\Roaming\Python\Python36\site-packages\django\core\handlers\base.py", line 143, in _get_response
    response = response.render()
  File "C:\Users\402995\AppData\Roaming\Python\Python36\site-packages\django\template\response.py", line 106, in render
    self.content = self.rendered_content
  File "C:\Users\402995\AppData\Roaming\Python\Python36\site-packages\django\template\response.py", line 83, in rendered_content
    content = template.render(context, self._request)
  File "C:\Users\402995\AppData\Roaming\Python\Python36\site-packages\django\template\backends\django.py", line 61, in render
    return self.template.render(context)
  File "C:\Users\402995\AppData\Roaming\Python\Python36\site-packages\django\template\base.py", line 171, in render
    return self._render(context)
  File "C:\Users\402995\AppData\Roaming\Python\Python36\site-packages\django\template\base.py", line 163, in _render
    return self.nodelist.render(context)
  File "C:\Users\402995\AppData\Roaming\Python\Python36\site-packages\django\template\base.py", line 937, in render
    bit = node.render_annotated(context)
  File "C:\Users\402995\AppData\Roaming\Python\Python36\site-packages\django\template\base.py", line 904, in render_annotated
    return self.render(context)
  File "C:\Users\402995\AppData\Roaming\Python\Python36\site-packages\django\template\loader_tags.py", line 150, in render
    return compiled_parent._render(context)
  File "C:\Users\402995\AppData\Roaming\Python\Python36\site-packages\django\template\base.py", line 163, in _render
    return self.nodelist.render(context)
  File "C:\Users\402995\AppData\Roaming\Python\Python36\site-packages\django\template\base.py", line 937, in render
    bit = node.render_annotated(context)
  File "C:\Users\402995\AppData\Roaming\Python\Python36\site-packages\django\template\base.py", line 904, in render_annotated
    return self.render(context)
  File "C:\Users\402995\AppData\Roaming\Python\Python36\site-packages\django\template\loader_tags.py", line 62, in render
    result = block.nodelist.render(context)
  File "C:\Users\402995\AppData\Roaming\Python\Python36\site-packages\django\template\base.py", line 937, in render
    bit = node.render_annotated(context)
  File "C:\Users\402995\AppData\Roaming\Python\Python36\site-packages\django\template\base.py", line 904, in render_annotated
    return self.render(context)
  File "C:\Users\402995\AppData\Roaming\Python\Python36\site-packages\django\template\defaulttags.py", line 443, in render
    url = reverse(view_name, args=args, kwargs=kwargs, current_app=current_app)
  File "C:\Users\402995\AppData\Roaming\Python\Python36\site-packages\django\urls\base.py", line 90, in reverse
    return iri_to_uri(resolver._reverse_with_prefix(view, prefix, *args, **kwargs))
  File "C:\Users\402995\AppData\Roaming\Python\Python36\site-packages\django\urls\resolvers.py", line 660, in _reverse_with_prefix
    raise NoReverseMatch(msg)
django.urls.exceptions.NoReverseMatch: Reverse for 'login' not found. 'login' is not a valid view function or pattern name.
"GET /accounts/login/?next=/wiki/The%2520Tuareg/edit HTTP/1.1" 500 150103
Not Found: /wiki/accounts/login/
"GET /wiki/accounts/login/ HTTP/1.1" 404 3909
Not Found: /
"GET / HTTP/1.1" 404 2264
Not Found: /favicon.ico
"GET /favicon.ico HTTP/1.1" 404 2315
Not Found: /dogs
"GET /dogs HTTP/1.1" 404 2294
Not Found: /Testpage/edit/delete
Not Found: /Testpage/edit/delete
Not Found: /Testpage/edit/
Not Found: /wiki/dogs/edit/delete
"GET /wiki/dogs/edit/delete HTTP/1.1" 404 4078
Not Found: /wiki/dogs/edit/delete_confirmation
"GET /wiki/dogs/edit/delete_confirmation HTTP/1.1" 404 4117
Not Found: /wikiTestpage/edit
Not Found: /wikiTestpage/edit
Not Found: /wikiTestpage/edit
Not Found: /wikiTestpage/edit/
Not Found: /
"GET / HTTP/1.1" 404 2264
Not Found: /favicon.ico
"GET /favicon.ico HTTP/1.1" 404 2315
Internal Server Error: /wiki/Testpage2/save
Traceback (most recent call last):
  File "C:\Users\402995\AppData\Roaming\Python\Python36\site-packages\django\utils\datastructures.py", line 78, in __getitem__
    list_ = super().__getitem__(key)
KeyError: 'content'

During handling of the above exception, another exception occurred:

Traceback (most recent call last):
  File "C:\Users\402995\AppData\Roaming\Python\Python36\site-packages\django\core\handlers\exception.py", line 34, in inner
    response = get_response(request)
  File "C:\Users\402995\AppData\Roaming\Python\Python36\site-packages\django\core\handlers\base.py", line 115, in _get_response
    response = self.process_exception_by_middleware(e, request)
  File "C:\Users\402995\AppData\Roaming\Python\Python36\site-packages\django\core\handlers\base.py", line 113, in _get_response
    response = wrapped_callback(request, *callback_args, **callback_kwargs)
  File "C:\Users\402995\AppData\Roaming\Python\Python36\site-packages\django\contrib\auth\decorators.py", line 21, in _wrapped_view
    return view_func(request, *args, **kwargs)
  File "D:\L3\Y2\Unit 27\Wiki\mywiki27\wiki\views.py", line 43, in save_page
    content = request.POST["content"]
  File "C:\Users\402995\AppData\Roaming\Python\Python36\site-packages\django\utils\datastructures.py", line 80, in __getitem__
    raise MultiValueDictKeyError(key)
django.utils.datastructures.MultiValueDictKeyError: 'content'
Internal Server Error: /wiki/Testpage2/save
Traceback (most recent call last):
  File "C:\Users\402995\AppData\Roaming\Python\Python36\site-packages\django\utils\datastructures.py", line 78, in __getitem__
    list_ = super().__getitem__(key)
KeyError: 'content'

During handling of the above exception, another exception occurred:

Traceback (most recent call last):
  File "C:\Users\402995\AppData\Roaming\Python\Python36\site-packages\django\core\handlers\exception.py", line 34, in inner
    response = get_response(request)
  File "C:\Users\402995\AppData\Roaming\Python\Python36\site-packages\django\core\handlers\base.py", line 115, in _get_response
    response = self.process_exception_by_middleware(e, request)
  File "C:\Users\402995\AppData\Roaming\Python\Python36\site-packages\django\core\handlers\base.py", line 113, in _get_response
    response = wrapped_callback(request, *callback_args, **callback_kwargs)
  File "C:\Users\402995\AppData\Roaming\Python\Python36\site-packages\django\contrib\auth\decorators.py", line 21, in _wrapped_view
    return view_func(request, *args, **kwargs)
  File "D:\L3\Y2\Unit 27\Wiki\mywiki27\wiki\views.py", line 43, in save_page
    content = request.POST["content"]
  File "C:\Users\402995\AppData\Roaming\Python\Python36\site-packages\django\utils\datastructures.py", line 80, in __getitem__
    raise MultiValueDictKeyError(key)
django.utils.datastructures.MultiValueDictKeyError: 'content'
Not Found: /
"GET / HTTP/1.1" 404 2264
Not Found: /favicon.ico
"GET /favicon.ico HTTP/1.1" 404 2315
Not Found: /upload
"GET /upload HTTP/1.1" 404 2300
Not Found: /wiki/The Tuareg/media/upload Tuareg.jpg
"GET /wiki/The%20Tuareg/media/upload%20Tuareg.jpg HTTP/1.1" 404 4136
Not Found: /wiki/The Tuareg/upload/ Tuareg.jpg
"GET /wiki/The%20Tuareg/upload/%20Tuareg.jpg HTTP/1.1" 404 4121
Not Found: /wiki/The Tuareg/upload/ Tuareg.jpg
"GET /wiki/The%20Tuareg/upload/%20Tuareg.jpg HTTP/1.1" 404 4121
Not Found: /wiki/The Tuareg/upload/Tuareg.jpg
"GET /wiki/The%20Tuareg/upload/Tuareg.jpg?raw=true HTTP/1.1" 404 4125
Not Found: /wiki/The Tuareg/upload/Tuareg.jpg
"GET /wiki/The%20Tuareg/upload/Tuareg.jpg?raw=true HTTP/1.1" 404 4125
Not Found: /wiki/The Tuareg/media/upload/Tuareg.jpg
"GET /wiki/The%20Tuareg/media/upload/Tuareg.jpg?raw=true HTTP/1.1" 404 4143
Not Found: /wiki/The Tuareg/media/upload/Tuareg.jpg
"GET /wiki/The%20Tuareg/media/upload/Tuareg.jpg?raw=true HTTP/1.1" 404 4143
Not Found: /wiki/The Tuareg/upload/Tuareg.jpg
"GET /wiki/The%20Tuareg/upload/Tuareg.jpg?raw=true HTTP/1.1" 404 4125
"GET /wiki/The%20Tuareg/upload/Tuareg.jpg?raw=true HTTP/1.1" 500 59
Not Found: /wiki/The Tuareg/upload/Tuareg.jpg
"GET /wiki/The%20Tuareg/upload/Tuareg.jpg?raw=true HTTP/1.1" 404 4125
"GET /wiki/The%20Tuareg/upload/Tuareg.jpg?raw=true HTTP/1.1" 500 59
